Workbook

Sheet XXXXXX
A1: ITEM | B1: SEDE | C1: AREA | D1: SUB AREA | E1: TRABAJADOR | F1: USUARIO | G1: NOMBRE PC | H1: IP | I1: TIPO | J1: MARCA | K1: PROCESADOR | L1: RAM | M1: DISCO | N1: T. VIDEO | O1: MONITOR | P1: TECLADO | Q1: MOUSE | R1: ESTABILIZADOR
A2: 1 | B2: 177 | C2: LOGISTICA | D2: Distribucción | E2: MAX CONDORI | F2: mcondori | G2: PC-COORDINADOR2 | I2: COMPUTADORA | J2: COMPATIBLE | K2: I5-11400 | L2: 16 GB | M2: 512 GB | O2: 20" | P2: SI | Q2: SI | R2: SI
A3: 2 | B3: 177 | C3: LOGISTICA | D3: Producción | E3: BRAIN DE LA CRUZ | F3: bdelacruz | G3: PC-DIGITACION3 | I3: COMPUTADORA | J3: COMPATIBLE | K3: I5-11400 | L3: 16 GB | M3: 512 GB | O3: 24" | P3: SI | Q3: LOGITECH K120 2252MR060BD8 | R3: SI
A4: 3 | B4: 177 | E4: BELEN CABELLO | F4: bcabello | G4: PC-IMPORTACION3 | I4: COMPUTADORA | J4: COMPATIBLE | K4: A12-9800E | L4: 8 GB | M4: 240 GB | O4: 24" | P4: SI | Q4: SI | R4: SI
A5: 4 | B5: 177 | C5: Facturación | E5: FRANK CULQUICONDOR | F5: fculquicondor | G5: PC-DIGITACION4 | I5: COMPUTADORA | J5: COMPATIBLE | K5: I5-11400 | L5: 16 GB | M5: 512 GB | O5: 24" | P5: SI | Q5: LOGITECH K120 2252MR060BF8 | R5: SI
A6: 5 | B6: 177 | C6: LOGISTICA | D6: Digitación | E6: Juan Carlos Llico Rudas | F6: digitacion | G6: LAP-CONTADOR6 | I6: LAPTOP | J6: DELL Inspiron 15 | K6: I5-1235U | L6: 8 GB | M6: NVME 2400A NVME Micron 512GB | O6: 15.6" | P6: SI | Q6: No | R6: SI
A7: 6 | B7: 177 | C7: CALIDAD | D7: CALIDAD | E7: VANESSA LOPEZ | F7: vlopez | G7: PC-CALIDAD2 | I7: COMPUTADORA | J7: COMPATIBLE | K7: I7-11700 | L7: 16 GB | M7: 512 GB | O7: 22" | P7: SI | Q7: SI | R7: SI
A8: 7 | B8: 177 | C8: CALIDAD | D8: CALIDAD | E8: MARIA ALEJANDRA MORAN | F8: mmoran | G8: PC-DESARROLLO1 | I8: COMPUTADORA | J8: COMPATIBLE | K8: I5-51400F | L8: 8 GB | M8: 240 GB | O8: 22" | P8: SI | Q8: LOGITECH K120 2021SC302T08 | R8: SI
A9: 8 | B9: 177 | C9: LOGISTICA | D9: DESPACHO | G9: LAP-SOPORTE | I9: LAPTOP | J9: Lenovo thinkpad 20J9S04A00 | K9: I7-7500U | L9: 16 GB drr4 2400mhz | M9: WD 2.5 240GB green | O9: 15.6" | P9: SI | Q9: SI | R9: SI
A10: 9 | B10: 177 | C10: Producción | D10: Producción | E10: JOSE RUA | F10: jrua | G10: PC-DESARROLLO2 | I10: COMPUTADORA | J10: COMPATIBLE | K10: INTEL PENTIUM G2010 | L10: 4 GB | M10: 240 GB | O10: 22" | P10: SI | Q10: LOGITECH K120 2244MR05B958 | R10: SI
A11: 10 | B11: 177 | C11: LOGISTICA | D11: DISTRIBUCION | E11: ALEX PAZ | F11: apaz | G11: PC-DISTRIBUCION | I11: COMPUTADORA | J11: COMPATIBLE | K11: I5-3330 | L11: 6 GB | M11: 240 GB | O11: 24" | P11: SI | Q11: SI | R11: SI
A12: 11 | B12: 177 | C12: LOGISTICA | D12: ALMACEN | E12: MURILLO | G12: LAP-GERENCIA1 | I12: LAPTOP | K12: I5-1235U | L12: 8 GB | M12: 512 GB | O12: 15.6" | P12: SI | Q12: SI | R12: SI
A13: 12 | B13: 177 | C13: LOGISTICA | D13: ALMACEN | E13: RICHARD SAPANA | F13: rsapana | G13: PC-MARKETING2 | I13: COMPUTADORA | J13: COMPATIBLE | K13: I5-11400F | L13: 16 GB | M13: 512 GB | O13: 22" | P13: SI | Q13: SI | R13: SI
A14: 13 | B14: 200 | C14: GGHH | D14: GGHH | E14: SANDRA YSLA | F14: sysla | G14: PC-GGHH | H14: 10.10.3.11 | I14: COMPUTADORA | J14: COMPATIBLE | K14: I5-11400F | L14: 8 GB | M14: 240 GB | O14: 22" | P14: SI | Q14: SI | R14: SI
A15: 14 | B15: 200 | C15: GGHH | D15: GGHH | E15: ERIC ORE | F15: eore | G15: LAP-RRHH | H15: 10.10.3.12 | I15: LAPTOP | J15: Lenovo IPEAD S145IIL | K15: I3-1005G1 | L15: 8GB 2400MHZ DDR4 | M15: SSD GIGABYTE GP-GSTFST31240GNTD | O15: 22" | P15: SI | Q15: SI | R15: no
A16: 15 | B16: 200 | C16: GGHH | D16: GGHH | E16: TASHINA MEJIA | F16: tmejia | G16: PC-RRHH | H16: 10.10.3.13 | I16: COMPUTADORA | J16: COMPATIBLE | K16: I5-4400 | L16: 8 GB | M16: 240 GB | O16: 19" | P16: SI | Q16: SI | R16: SI
A17: 16 | B17: 200 | C17: GGHH | D17: SSOMA | E17: KEVIN GUILLEN | F17: kguillen | G17: PC-SSOMA | H17: 10.10.3.14 | I17: COMPUTADORA | J17: COMPATIBLE | K17: I3-4170 | L17: 8 GB | M17: 240 GB | O17: 19" | P17: SI | Q17: GENIUS KB115 X1D21043404094 | R17: SI
A18: 17 | B18: 200 | C18: SUBGERENCIA | D18: SUBGERENCIA | E18: ENRIQUE DAMACEN | G18: LAP-SUBGERENTE | H18: 10.10.3.15 | I18: LAPTOP | K18: I7-1360P | L18: 16 GB | M18: 1 TB | O18: 16" | P18: SI | Q18: SI | R18: SI
A19: 18 | B19: 200 | C19: SUPERVISION | D19: SUPERVISION | E19: VICTOR ORTIZ | F19: vortiz | G19: PC-FINANZAS | H19: 10.10.3.16 | I19: COMPUTADORA | J19: COMPATIBLE | K19: I5-1400F | L19: 8 GB | M19: 512 GB | O19: 22" | P19: SI | Q19: SI | R19: SI
A20: 19 | B20: 200 | C20: CONTABILIDAD | D20: CONTABILIDAD | E20: MIJAIL VILLAVERDE | F20: mvillaverde | G20: PC-CONTA1 | H20: 10.10.3.17 | I20: COMPUTADORA | J20: COMPATIBLE | K20: I5-11400 | L20: 8 GB | M20: 240 GB | O20: 22" | P20: SI | Q20: SI | R20: SI
A21: 20 | B21: 200 | C21: CONTABILIDAD | D21: CONTABILIDAD | E21: VALERY SANCHEZ | F21: msanchez | G21: PC-CONTA2 | H21: 10.10.3.18 | I21: COMPUTADORA | J21: COMPATIBLE | K21: I3-4160 | L21: 4 GB | M21: 240 GB | O21: 22" | P21: SI | Q21: SI | R21: SI
A22: 21 | B22: 200 | C22: CONTABILIDAD | D22: CONTABILIDAD | E22: CESAR MONTALVO | F22: cmontalvo | G22: PC-CONTA5 | H22: 10.10.3.19 | I22: COMPUTADORA | J22: COMPATIBLE | K22: A12-9800E | L22: 8 GB | M22: 240 GB | O22: 24" | P22: SI | Q22: SI | R22: SI
A23: 22 | B23: 200 | C23: IMPORTACIONES | D23: IMPORTACIONES | E23: Emily Dianira Montoya Palma | F23: emontoya | G23: LAP-DAMACENG | H23: 10.10.3.21 | I23: LAPTOP | J23: LENOVO THINKPAD L15 GEN 1 | K23: I5-1021U | L23: 16GB 3200MHZ DDR4 | M23: 240 GB SSD sata | O23: 15.6" | P23: SI | Q23: SI | R23: SI
A24: 23 | B24: 200 | C24: LOGISTICA | D24: IMPORTACIONES | E24: EMILY MONTOYA | F24: emontoya | G24: PC-IMPORT1 | H24: 10.10.3.22 | I24: COMPUTADORA | J24: COMPATIBLE | K24: I5-6400 | L24: 8 GB | M24: 240 GB | O24: 22" | P24: SI | Q24: SI | R24: SI
A25: 24 | B25: 200 | C25: LOGISTICA | D25: IMPORTACIONES | E25: PAULO ROJAS | F25: projas | G25: LAP-PLANNER | H25: 10.10.3.23 | I25: LAPTOP | J25: Laptop Asus Vivobook | K25: I7-12700 | L25: 16GB 3200MHZ DRR4 | M25: NVME M.2 MTFDKBK512QFM 512GB | O25: 16" | P25: SI | Q25: SI | R25: SI
A26: 25 | B26: 200 | C26: LOGISTICA | D26: IMPORTACIONES | E26: LUIS PARE | F26: lpare | G26: PC-FACTURACION4 | H26: 10.10.3.24 | I26: COMPUTADORA | J26: COMPATIBLE | K26: I5-11400 | L26: 16 GB | M26: 240 GB | O26: 22" | P26: SI | Q26: SI | R26: SI
A27: 26 | B27: 200 | C27: LOGISTICA | D27: ALMACEN | E27: VICTOR HUAMAN | F27: vhuaman | G27: DESKTOP-007M481 | H27: 10.10.3.25 | I27: LAPTOP | K27: I3-2330M | L27: 8 GB | M27: 512 GB | O27: 14" | P27: SI | Q27: SI | R27: SI
A28: 27 | B28: 200 | C28: FINANZAS | D28: TESORERIA | E28: KRISTELL QUISPE | F28: kquispe | G28: PC-CONTA3 | H28: 10.10.3.26 | I28: COMPUTADORA | J28: COMPATIBLE | K28: I3-7100 | L28: 8 GB | M28: 240 GB | O28: 22" | P28: SI | Q28: SI | R28: SI
A29: 28 | B29: 200 | C29: FINANZAS | D29: TESORERIA | E29: ANTHONY MENDOZA | F29: amendoza | G29: PC-CONTA6 | H29: 10.10.3.27 | I29: COMPUTADORA | J29: COMPATIBLE | K29: A12-9800E | L29: 8 GB | M29: 240 GB | O29: 22" | P29: SI | Q29: SI | R29: SI
A30: 29 | B30: 200 | C30: FINANZAS | D30: COBRANZAS | E30: PEDRO ESPEJO | F30: aespejo | G30: PC-COBRANZA1 | H30: 10.10.3.28 | I30: COMPUTADORA | J30: COMPATIBLE | K30: A12-9800E | L30: 8 GB | M30: 240 GB | O30: 24" | P30: SI | Q30: SI | R30: SI
A31: 30 | B31: 200 | C31: FINANZAS | D31: COBRANZAS | E31: WILMER AMASIFUEN | F31: wamasifuen | G31: PC-COBRANZA2 | H31: 10.10.3.29 | I31: COMPUTADORA | J31: COMPATIBLE | K31: I3-4170 | L31: 8 GB | M31: 240 GB | O31: 22" | P31: SI | Q31: SI | R31: SI
A32: 31 | B32: 200 | C32: FINANZAS | D32: COBRANZAS | E32: MARIA LUISA LUYO | F32: mluyo | G32: PC-COBRANZA3 | H32: 10.10.3.31 | I32: COMPUTADORA | J32: COMPATIBLE | K32: I3-2120 | L32: 4 GB | M32: 240 GB | O32: 22" | P32: SI | Q32: SI | R32: SI
A33: 32 | B33: 200 | C33: FINANZAS | D33: COBRANZAS | E33: MIRKO PARI | F33: mpari | G33: PC-VENTAS1 | H33: 10.10.3.32 | I33: COMPUTADORA | J33: COMPATIBLE | K33: I5-4170 | L33: 8 GB | M33: 240 GB | O33: 24" | P33: SI | Q33: SI | R33: SI
A34: 33 | B34: 200 | C34: SISTEMAS | D34: SISTEMAS | E34: EDWYN MONTORO | F34: emontoro | G34: PC-SISTEMAS1 | H34: 10.10.3.33 | I34: COMPUTADORA | J34: COMPATIBLE | K34: I7-11200 | L34: 16 GB | M34: 512 GB | O34: 24" | P34: SI | Q34: SI | R34: SI
A35: 34 | B35: 200 | C35: SISTEMAS | D35: SISTEMAS | E35: JOSEMI VASQUEZ | G35: PC-FACTURACION3 | H35: 10.10.3.34 | I35: COMPUTADORA | J35: COMPATIBLE | K35: I5-11400 | L35: 16 GB | M35: 512 GB | O35: 19" | P35: SI | Q35: SI | R35: SI
A36: 35 | B36: 200 | C36: SISTEMAS | D36: SISTEMAS | E36: JUAN NIMA | F36: jnima | G36: DESKTOP-OFKJ2SJ | H36: 10.10.3.35 | I36: LAPTOP | J36: DELL | K36: I7-1360P | L36: 16 GB | M36: 1 TB | O36: 24" | P36: SI | Q36: SI | R36: NO
A37: 36 | B37: 200 | C37: CALIDAD | D37: CALIDAD | E37: DEYSI VANNESA LOPEZ MORAN | F37: dlopez | G37: LAP-GERENCIA2 | H37: 10.10.3.36 | I37: LAPTOP | J37: DELL INSPIRON 15 | K37: I7-1255U | L37: 16GB DRR4 3200MHZ | M37: Nvme BG6KIOXIA 1024GB | O37: 15.6" | P37: SI | Q37: SI | R37: SI
A38: 37 | B38: 200 | C38: DESARROLLO | D38: DESARROLLO | E38: DIK SALDAÑA | F38: dsaldaña | G38: PC-DESARROLLO | H38: 10.10.3.37 | I38: COMPUTADORA | J38: COMPATIBLE | K38: I7-11700 | L38: 16 GB | M38: 512 GB | O38: 24" | P38: SI | Q38: LOGITECH K120 2232MR046B88 | R38: SI
A39: 38 | B39: 200 | C39: DESARROLLO | D39: DESARROLLO | E39: GUSTAVO SILVA | F39: gsilva | G39: PC-ALMACEN3 | H39: 10.10.3.38 | I39: COMPUTADORA | J39: COMPATIBLE | K39: I5-11400 | L39: 8 GB | M39: 240 GB | O39: 22" | P39: SI | Q39: LOGITECH K120 2021SC302SZ8 | R39: SI
A40: 39 | B40: 200 | C40: COMERCIAL | D40: VENTAS | E40: MARIELA CASTAÑEDA | F40: mcastañeda | G40: LAP-GCOMERCIAL | H40: 10.10.3.39 | I40: LAPTOP | J40: ASUS | K40: I7-12700 | L40: 16 GB | M40: 512 GB | O40: 16" | P40: SI | Q40: SI | R40: SI
...

Sheet INVENTARIO CONSOLIDADO
A1: ITEM | B1: SEDE | C1: AREA | D1: SUB AREA | E1: TRABAJADOR | F1: USUARIO | G1: NOMBRE PC | H1: IP | I1: TIPO | J1: MARCA | K1: PLACA MADRE | L1: PROCESADOR | M1: GEN | N1: DESCPROCESADOR | O1: RAM | P1: DISCO | Q1: DESCDISCO | R1: T. VIDEO | S1: MONITOR | T1: TECLADO | U1: MOUSE | V1: ESTABILIZADOR | W1: Observaciones
A2: 22 | B2: 200 | C2: IMPORTACIONES | D2: IMPORTACIONES | E2: Emily Dianira Montoya Palma | F2: emontoya | G2: LAP-DAMACENG | H2: 10.10.3.21 | I2: LAPTOP | J2: LENOVO THINKPAD L15 GEN 1 | K2: Laptop L15 GEN 1 | L2: I5 | M2: 10 | N2: I5-1021U | O2: 16GB 3200MHZ DDR4 | P2: SATA 240GB | Q2: 240 GB SSD sata | S2: 15.6" | T2: SI | U2: SI | V2: Forza FVR 902
A3: 24 | B3: 200 | C3: LOGISTICA | D3: IMPORTACIONES | E3: PAULO ROJAS | F3: projas | G3: LAP-PLANNER | H3: 10.10.3.23 | I3: LAPTOP | J3: Laptop Asus Vivobook | K3: Laptop Asus Vivobook | L3: I7 | M3: 12 | N3: I7-12700 | O3: 16GB 3200MHZ DRR4 | P3: M.2 | Q3: NVME M.2 MTFDKBK512QFM 512GB | S3: 16" | T3: SI | U3: SI | V3: Forza FVR 903
B4: 177 | C4: COMERCIAL | D4: VENTAS | E4: JORGE RIOS | F4: jrios | G4: LAP-VENTAS | I4: LAPTOP | J4: Laptop ipead s340-15iwl | K4: Laptop ipead s340-15iwl | L4: I5 | M4: 8 | N4: I5-8265U | O4: 12 GB 2400Mhz DDR4 | Q4: Kingston SA400S37240G 240GB | R4: INTEGRADA | S4: 15.6" | T4: SI | U4: No | V4: PLI 1100 USB
B5: 177 | C5: COMERCIAL | D5: VENTAS | E5: Juan Pablo Quiroz Auqui | F5: jquiroz | G5: LAP-FINANZAS | I5: LAPTOP | J5: DELL Inspiron 15 | K5: LAPTOP DELL INSPIRION15 3520 | L5: I7 | M5: 12 | N5: I7-1255U | O5: 16GB DRR4 3200MHZ | Q5: NVME BG6 KIOXIA 1024GB | R5: INTEGRADA | S5: 15.6" | T5: SI | U5: No | V5: SI
A6: 5 | B6: 177 | C6: GGHH | D6: GGHH | E6: ERIC ORE | F6: eore | G6: LAP-RRHH | I6: LAPTOP | J6: Lenovo IPEAD S145IIL | K6: Lenovo IPEAD S145IIL | L6: I3 | M6: 10 | N6: I3-1005G1 | O6: 8GB 2400MHZ DDR4 | Q6: SSD GIGABYTE GP-GSTFST31240GNTD 240GB | R6: INTEGRADA | S6: 15.6" | T6: SI | U6: No | V6: SI
A7: 5 | B7: 177 | C7: LOGISTICA | D7: Digitación | E7: Juan Carlos Llico Rudas | F7: digitacion | G7: LAP-CONTADOR6 | I7: LAPTOP | J7: DELL Inspiron 15 | K7: DELL Inspiron 15 | L7: I5 | M7: 12 | N7: I5-1235U | O7: 8GB 3200mhz DDR4 | Q7: NVME 2400A NVME Micron 512GB | R7: INTEGRADA | S7: 15.6" | T7: SI | U7: No | V7: SI
A8: 8 | B8: 177 | C8: LOGISTICA | D8: DESPACHO | G8: LAP-SOPORTE | I8: LAPTOP | J8: Lenovo thinkpad 20J9S04A00 | K8: Lenovo thinkpad 20J9S04A00 | L8: I7 | M8: 7 | N8: I7-7500U | O8: 16 GB drr4 2400mhz | Q8: WD 2.5 240GB green | R8: INTEGRADA | S8: 15.6" | T8: SI | U8: SI | V8: SI
A9: 36 | B9: 200 | C9: CALIDAD | D9: CALIDAD | E9: DEYSI VANNESA LOPEZ MORAN | F9: dlopez | G9: LAP-GERENCIA2 | H9: 10.10.3.36 | I9: LAPTOP | J9: DELL INSPIRON 15 | K9: DELL INSPIRON 15 | L9: I7 | M9: 12 | N9: I7-1255U | O9: 16GB DRR4 3200MHZ | Q9: Nvme BG6KIOXIA 1024GB | R9: INTEGRADA | S9: 15.6" | T9: SI | U9: SI | V9: SI
A10: 26 | B10: 200 | C10: LOGISTICA | D10: ALMACEN | E10: VICTOR HUAMAN | F10: vhuaman | G10: DESKTOP-007M481 | H10: 10.10.3.25 | I10: LAPTOP | J10: HP PAVILLION G SERIES | K10: HP PAVILLION G SERIES | L10: I3 | M10: 2 | N10: I3-2330M | O10: 4 GB DDR3 1600MHZ | Q10: 512 GB ssd sata | R10: INTEGRADA | S10: 14" | T10: SI | U10: SI | V10: SI
A11: 51 | B11: 200 | C11: COMERCIAL | D11: VENTAS | E11: JORGE RIOS | F11: jrios | G11: LAP-VENTAS1 | H11: 10.10.3.53 | I11: LAPTOP | J11: Laptop ipead s340-15iwl | K11: Laptop ipead s340-15iwl | L11: I5 | M11: 8 | N11: I5-8265U | O11: 12 GB 2400Mhz drr4 | Q11: Kingston SA400S37240G 240GB | R11: INTEGRADA | S11: 14" | T11: SI | U11: SI | V11: SI
A12: 35 | B12: 200 | C12: SISTEMAS | D12: SISTEMAS | E12: DOMINICK ORTIZ | F12: dortiz | G12: DESKTOP-OFKJ2SJ | H12: 10.10.3.35 | I12: LAPTOP | J12: DELL INSPIRON 16 2-IN-1 | K12: DELL INSPIRON 16 2-IN-1 | L12: I7 | M12: 13 | N12: I7-1360P | O12: 16 GB drr4 3200MHZ | Q12: NVME BG6 KIOXIA 1024GB | R12: INTEGRADA | S12: 15.6" | T12: SI | U12: SI | V12: NO
A13: 25 | B13: 200 | C13: LOGISTICA | D13: IMPORTACIONES | E13: Luis Pare | F13: Lpare | G13: PC-FACTURACION4 | H13: 10.10.3.24 | I13: COMPUTADORA | J13: COMPATIBLE | K13: B560M gigabyte | L13: I3 | M13: 7 | N13: I3-7100U | O13: 16GB 3200mhz drr4 | Q13: WD 2.5 ssd sata 240GB | S13: Samsung S24R35AFHN 24" | T13: SI | U13: SI | V13: forza fvr 902 | W13: Teclado desgastado, mouse desgastado, pc mantenimiento suciedad en todo el case
A14: 31 | B14: 200 | C14: FINANZAS | D14: COBRANZAS | E14: Luisa Luyo | F14: mluyo | G14: PC-COBRANZA3 | H14: 10.10.3.31 | I14: COMPUTADORA | J14: COMPATIBLE | K14: H61M-DS2 Gigabyte | L14: I7 | M14: 4 | N14: I7-4790 | O14: 4GB 1333mhz drr3 | Q14: WD 2.5 240GB | S14: Samsung S22F350FHL 22" | T14: SI | U14: SI | V14: Estabilizador forza fvr 902 | W14: Lentitud de pc por componentes antiguos cambio de pc, Teclado las teclas no se ven.
B15: 200 | C15: COMERCIAL | D15: VENTAS | E15: Nataly Cruz | F15: ncruz | G15: PC-TDA3 | I15: COMPUTADORA | J15: COMPATIBLE | K15: H110M-H Gigabyte | L15: I3 | M15: 7 | N15: I3-7100 | O15: 8GB 2400 MHZ DRR4 | Q15: WD 2.5 240GB | S15: Samsung S22FJ350FHL | T15: SI | U15: SI | V15: Estabilizador FVR 1202USB | W15: PC con polvo futuro mantenimiento
A16: 27 | B16: 200 | C16: FINANZAS | D16: TESORERIA | E16: Kristell Quispe | F16: kquispe | G16: PC-CONTA3 | H16: 10.10.3.26 | I16: COMPUTADORA | J16: COMPATIBLE | K16: Asus prime H110M-P | L16: I3 | M16: 7 | N16: I3-7100U | O16: 8GB 3200MHZ DRR4 2 módulos de 4 | Q16: SSD Kingston SA400S37240G 240GB | S16: Samsung F22T350FHL | T16: SI | U16: SI | V16: TAIR PLI 1100USB | W16: PC con polvo continuo en el case, futuro mantenimiento
A17: 30 | B17: 200 | C17: FINANZAS | D17: COBRANZAS | E17: Wilmer amasifuen | F17: wamasifuen | G17: PC-COBRANZA2 | H17: 10.10.3.29 | I17: COMPUTADORA | J17: COMPATIBLE | K17: H810M-H Gigabyte | L17: I5 | M17: 6 | N17: I5-6400 | O17: 8GB 1600MHZ DRR3 | Q17: Kingston SA400S37240G 240GB | S17: S22F35FHLXPE Samsung 22" | T17: SI | U17: SI | V17: Gambyte | W17: Mantenimiento pc sucia, componentes antiguos necesita actualización de equipo, lentitud de equipo
A18: 29 | B18: 200 | C18: FINANZAS | D18: COBRANZAS | E18: Mirko Pari | F18: mpari | G18: PC-COBRANZA1 | H18: 10.10.3.28 | I18: COMPUTADORA | J18: COMPATIBLE | K18: Asus prime H510M-K R2.0 | L18: I7 | M18: 11 | N18: I7-11700 | O18: 8GB 2600 MHZ drr4 | Q18: MSI SPATIUM 240GB | S18: S24R35AFHN Samsung 24" | T18: SI | U18: SI | V18: No cuenta | W18: Pc sucia mantenimiento futuro
A19: 43 | B19: 200 | C19: COMERCIAL | D19: VENTAS | E19: Pedro Espejo | F19: pespejo | G19: PC-CAMPO7 | H19: 10.10.3.44 | I19: COMPUTADORA | J19: COMPATIBLE | K19: Asustes PRIME A320M-K | L19: I7 | M19: 11 | N19: I7-11700 | O19: 8GB 1200MHZ drr3 | Q19: Kingston SA400S37240G 240GB | S19: S24R35AFHN Samsung 24" | T19: SI | U19: SI | V19: Forza FVR 902 | W19: Mantenimiento de pc suciedad en el case y componentes
A20: 47 | B20: 200 | C20: COMERCIAL | D20: VENTAS | E20: Eduardo Rojas | F20: jrios | G20: PC-DIGITACION2 | H20: 10.10.3.48 | I20: COMPUTADORA | J20: COMPATIBLE | K20: Asustek Prime A320MK | L20: I5 | M20: 10 | N20: I5-10400F | O20: 8GB 1200MHZ Drr3 | Q20: Kingston SA400S37240G 240GB | S20: 19M38A-B LG 19" | T20: SI | U20: SI | V20: Forza-1002 | W20: Problemas de energía, pc mantenimiento sucio case y componentes
B21: 200 | C21: COMERCIAL | D21: VENTAS | E21: Jhon Rashta | F21: jrashta | G21: PC-HORECA | I21: COMPUTADORA | J21: COMPATIBLE | K21: H61H2-MV ECS | L21: I5 | M21: 11 | N21: I5-11400 | O21: 4GB drr3 1600mhz | Q21: Kingston SA400S37240G 240GB | S21: 24mk430h-b LG 24" | T21: SI | U21: SI | V21: TAIR PLI 1100USB | W21: Pc con lentitud, hardaware desactualizado, monitor con raya de Led desgaste.
A22: 45 | B22: 200 | C22: COMERCIAL | D22: VENTAS | E22: Carlo Alva Gamarra | F22: jroman | G22: PC-DIGITACION1 | H22: 10.10.3.46 | I22: COMPUTADORA | J22: COMPATIBLE | K22: Intel B250 | L22: AMD | N22: AMD A12 9800E-9800 | O22: 8GB 2133 MHZ drr4 | Q22: Gigabyte GP-GSTFS31240GNTD 240GB | S22: 19M38A-B LG 19" | T22: SI | U22: SI | V22: Forza FVR 902 | W22: Mouse problemas, mantenimeinto de pc por temperatura
A23: 49 | B23: 200 | C23: COMERCIAL | D23: VENTAS | E23: Ricardo Rojas | F23: rrojas | G23: PC-PROVINCIAS | H23: 10.10.3.51 | I23: NUC | J23: NUC | K23: H61M-DS2 3.0 | L23: I3 | M23: 4 | N23: I3-4160 | O23: 4GB 1333 MHZ DRR3 | Q23: Kingston SA400S37240G 240GB | S23: 24mk430h-b LG 24" | T23: SI | U23: SI | V23: Forza FVR 902 | W23: Teclado desgastado, cable de video y puerto y mantenimeinto de pc por temperatura falta
B24: 200 | C24: COMERCIAL | D24: VENTAS | E24: Virgilio gutierrez | F24: vgutierrez | G24: PC-VENTAS4 | H24: 10.10.3.51 | I24: NUC | J24: NUC | K24: NUC7i3BNB | L24: AMD | N24: AMD A12-9800E Radeon R7 12 Compute cores 4c+8G | O24: 8GB 2133 MHZ drr4 | Q24: Kingston SA400S37240G 240GB | S24: 22MK400H-B LG | T24: SI | U24: SI | V24: CDP RU-AVR | W24: Mantenimiento su mini PC
A25: 44 | B25: 200 | C25: COMERCIAL | D25: VENTAS | E25: Omar Yarleque | F25: fleon | G25: PC-ALMACEN1 | H25: 10.10.3.45 | I25: COMPUTADORA | J25: COMPATIBLE | K25: H810M-H Gigabyte | L25: I5 | M25: 9 | N25: I5-9400F | O25: 8GB 1600 MHZ DDR3 | Q25: Gigabyte GP-GSTF31240GNTD | S25: 19M37A-B LG | T25: SI | U25: SI | V25: Corriente directa | W25: Mantenimeinto de pc, cambio de teclado y mouse desgaste
A26: 46 | B26: 200 | C26: COMERCIAL | D26: VENTAS | E26: Jefferson Paz | F26: jpaz | G26: PC-MAYORISTA2 | H26: 10.10.3.47 | I26: NUC | J26: NUC | K26: Asustek Prime H110M-P | L26: I7 | M26: 11 | N26: I7-11700 | O26: 8GB 2400mhz DDR4 | Q26: WD 2.5 240GB | S26: 24mk430h-b LG 24" | T26: SI | U26: SI | V26: UPS BX800L-MS | W26: Congelamiento con pc, mantenimiento pc, Teclado esta mal.
A27: 41 | B27: 200 | C27: COMERCIAL | D27: VENTAS | E27: Juditza Gonzales | F27: jgonzales | G27: PC-VENTAS2 | H27: 10.10.3.42 | I27: COMPUTADORA | J27: COMPATIBLE | K27: NUC7I3BNB intel | L27: I3 | M27: 4 | N27: I3-4170 | O27: 8GB 2100MHZ DDR4 | Q27: Kingston SA400S37240G 240GB | S27: S24R35AFHN Samsung 24" | T27: SI | U27: SI | V27: UPS SPS ONE SALICRU, | W27: Mantenimeinto pc físico y digital
A28: 48 | B28: 200 | C28: COMERCIAL | D28: VENTAS | E28: Rosselyn Morante | F28: rmorante | G28: PC-SISTEMAS2 | H28: 10.10.3.49 | I28: COMPUTADORA | J28: COMPATIBLE | K28: H110M-H-CF | L28: I5 | M28: 4 | N28: I5-4440 | O28: 8GB 2100MHZ DDR4 | Q28: WD 2.5 240GB | S28: 22M38H-B LG | T28: SI | U28: SI | V28: UPS SALICRU SPS ONE, forza fvr 1110 | W28: Fuente de poder ventilador no funciona, mantenimiento a pc general
A29: 42 | B29: 200 | C29: COMERCIAL | D29: VENTAS | E29: Alexandra Roman | F29: jbarboza | G29: PC-VENTAS3 | H29: 10.10.3.43 | I29: COMPUTADORA | J29: COMPATIBLE | K29: B560M D3SH | L29: I5 | M29: 11 | N29: I5-11400F | O29: 16GB 2666MHZ DDR4 | Q29: CT500P2SSD8 500GB | S29: S24R35AFHN Samsung 24" | T29: SI | U29: SI | V29: UPS SALICRU SPS ONE | W29: Mantenimiento PC temperatura alta
A30: 40 | B30: 200 | C30: COMERCIAL | D30: VENTAS | E30: Lesly Quispe | F30: lquispe | G30: PC-PROVINCIA2 | H30: 10.10.3.41 | I30: COMPUTADORA | J30: COMPATIBLE | K30: B560M Gaming HD Gigabyte | L30: I5 | M30: 11 | N30: I5-11400 | O30: 16GB 2666MHZ DDR4 | Q30: DAHUA C900 2280 NVME 512GB M.2 | S30: 24MK430H-B LG 24" | T30: SI | U30: SI | V30: UPS SALICRU SPS ONE | W30: Mantenimiento PC temperatura alta
A31: 40 | B31: 200 | C31: COMERCIAL | D31: VENTAS | E31: Walter Vasquez | F31: wvasquez | G31: PC-IMPORTACIONES2 | H31: 10.10.3.41 | I31: COMPUTADORA | J31: COMPATIBLE | K31: H410M S2H V2 | L31: I5 | M31: 11 | N31: I5-11400 | O31: 8GB 2600 MHZ DDR4 | Q31: CT480BX500SSD1 480 SSD | S31: F24T350FHL Samsung 24" | T31: SI | U31: SI | V31: Forza FVR 902 | W31: Insuficiente memoria ram, se apaga solo, mantenimiento pc por temperatura.
A32: 21 | B32: 200 | C32: CONTABILIDAD | D32: CONTABILIDAD | E32: Merly Flores | F32: acontable | G32: PC-CONTA5 | H32: 10.10.3.19 | I32: COMPUTADORA | J32: COMPATIBLE | K32: PRIME H510M-K R2.0 | L32: AMD | N32: AMD A12 9800E RADEON R7 12 COMPUTER | O32: 8GB 2666MHZ DDR4 | Q32: Kingston SA400S37240G 240GB | S32: 20M47A-B LG | T32: SI | U32: SI | V32: Gambyte | W32: Insuficiente memoria ram, mantenimiento por temperatura alta
A33: 19 | B33: 200 | C33: CONTABILIDAD | D33: CONTABILIDAD | E33: Cesar Montalvo | F33: cmontalvo | G33: PC-CONTA1 | H33: 10.10.3.17 | I33: COMPUTADORA | J33: COMPATIBLE | K33: Prime A320M-K | L33: I5 | M33: 11 | N33: I5-11400 | O33: 8GB 1200MHZ DDR3 | Q33: WD 2.5 GREEN 240GB | S33: S24R35AFHN Samsung 24" | T33: SI | U33: SI | V33: Quedar modelo | W33: Mantenimeinto pc, componentes obsoletos
A34: 20 | B34: 200 | C34: CONTABILIDAD | D34: CONTABILIDAD | E34: Maria Valery Sanchez Camino | F34: msanchez | G34: PC-CONTA2 | H34: 10.10.3.18 | I34: COMPUTADORA | J34: COMPATIBLE | K34: H810M-H Gigabyte | L34: I5 | M34: 11 | N34: I5-11400F | O34: 4GB 1600MHZ DDR3 | Q34: WD 2.5 Green 240GB | S34: 22MK400H-B LG 22"" | T34: SI | U34: SI | V34: Forza FVR 902 | W34: Mantenimiento pc, ampliación de memoria ram insuficiente
A35: 28 | B35: 200 | C35: FINANZAS | D35: TESORERIA | E35: Anthony Mendoza | F35: amendoza | G35: PC-CONTA6 | H35: 10.10.3.27 | I35: COMPUTADORA | J35: COMPATIBLE | K35: Prime A320M-K | L35: I5 | M35: 11 | N35: I5-11400 | O35: 8GB 1200MHZ DDR3 | Q35: Kingston SA400S37240G 240GB | S35: 22M38H-B LG 22" | T35: SI | U35: SI | V35: Forza FVR 902 | W35: Lentitud ordenador urgente, cuelgue de la maquina constante, mantenimiento ordenador.
A36: 18 | B36: 200 | C36: SUPERVISION | D36: SUPERVISION | E36: Victor Ortiz | F36: vortiz | G36: PC-FINANZAS | H36: 10.10.3.16 | I36: COMPUTADORA | J36: COMPATIBLE | K36: H310M H 2m0 | L36: PENTIUM | N36: Intel pentium G2010 | O36: 8GB 2666MHZ DDR4 | Q36: WDC WDS480G2G0A-00JH30 480GB | S36: S22F35FHLXPE Samsung 22" | T36: SI | U36: SI | V36: Estabilizador | W36: Lentitud ordenador, mantenimiento y upgrade memoria ram
A37: 50 | B37: 200 | C37: COMERCIAL | D37: MARKETING | E37: Alexander Flores | F37: fleon | G37: PC-MARKETING | H37: 10.10.3.52 | I37: COMPUTADORA | J37: COMPATIBLE | K37: B560M Gigabyte | L37: I5 | M37: 3 | N37: I5-3330 | O37: 16GB | Q37: SSD 500 CT480BX500SSD1 | R37: NVIDA GTX 1650 | S37: FN24T350FHL, SAMSUNG, 24" | T37: SI | U37: SI | V37: FORZA FVR 902 | W37: Pantallazo Azul, tiene freeze el ordenador, memoria ram un modulo defectuosa, ya que es una compatible y no original
A38: 16 | B38: 200 | C38: GGHH | D38: SSOMA | E38: Adrian Gonzales | F38: agonzales | G38: PC-SSOMA | H38: 10.10.3.14 | I38: COMPUTADORA | J38: COMPATIBLE | K38: H810M-H | L38: I7 | M38: 11 | N38: I7-11700 | O38: 8GB 1600MHZ DDR3 | Q38: Kingston SA400S37240G 240GB | S38: 19M38A-B LG 19" | T38: SI | U38: GENIUS KB115 X1D21043404094 | V38: Forza FVR 902 | W38: Pc lenta, memoria ram insuficiente
A39: 15 | B39: 200 | C39: GGHH | D39: GGHH | E39: Tashina | F39: usuariorh | G39: PC-RRHH | H39: 10.10.3.13 | I39: COMPUTADORA | J39: COMPATIBLE | K39: H81M-S1 | L39: I7 | M39: 11 | N39: I7-11700 | O39: 8GB 1600MHZ DDR3 | Q39: Kingston SA400S37240G 240GB | S39: 19M38A-B LG 19" | T39: SI | U39: SI | V39: Forza FVR 902 | W39: Lentitud por falta de memoria ram
A40: 13 | B40: 200 | C40: GGHH | D40: GGHH | E40: Sandra Ysla | F40: sysla | G40: PC-GGHH | H40: 10.10.3.11 | I40: COMPUTADORA | J40: COMPATIBLE | K40: H510M-VHS Asrock | L40: I5 | M40: 11 | N40: I5-11400F | O40: 8GB DDR4 3200mhz | Q40: CT240XBX500SSD1 500GB | S40: LF22T350FHLXPE SAMSUNG 22" | T40: SI | U40: SI | V40: Forza FVR 902 | W40: Lentitud memoria ram corto, mantenimiento PC
...

Sheet TD1
A3: AREA | B3: SubArea | C3: Estado2Valor | D3: Estado2 | E3: Responsable | F3: HOSTNAME | G3: DESCPROCESADOR | H3: DESCRAM | I3: usuario | J3: SEDE
A4: CALIDAD | B4: Calidad | C4: 5 | D4: BUENA | E4: Deysi Lopez | F4: LAP-GERENCIA2 | G4: I7-1255U | H4: 16GB DRR4 3200MHZ | I4: dlopez | J4: 177
E5: Maria Moran | F5: PC-FACTURACION3 | G5: I5-11400 | H5: 16GB 3200mhz DDR4 | I5: mmoran | J5: 177
C6: 3 | D6: OPTIMO - REPOTENCIAR | E6: Gustavo Silva | F6: PC-DESARROLLO1 | G6: I5-11400F | H6: 8GB 3200MHZ DDR4 | I6: mmoran | J6: 177
A7: COMERCIAL | B7: Marketing | C7: 4 | D7: BUENA - REPOTENCIAR | E7: Alexander Flores | F7: PC-MARKETING | G7: I7-11700 | H7: 16GB | I7: fleon | J7: 200
B8: Ventas | C8: #N/D | D8: (en blanco) | E8: I5 | F8: COMPUTADORA | G8: RYZEN 7-7735HS | H8: 16GB 5200 MHZ DDR5 | I8: Jhon Rashta | J8: CAMBIO
C9: 5 | D9: BUENA | E9: Alexandra Roman | F9: PC-SISTEMAS2 | G9: I7-11700 | H9: 16GB 2666MHZ DDR4 | I9: jbarboza | J9: 200
E10: Juan Pablo Quiroz Auqui | F10: LAP-FINANZAS | G10: I7-1255U | H10: 16GB | I10: jquiroz | J10: 200
E11: Lesly Quispe | F11: PC-VENTAS3 | G11: I7-11700 | H11: 16GB 2666MHZ DDR4 | I11: lquispe | J11: 200
C12: 3 | D12: OPTIMO - REPOTENCIAR | E12: Walter Vasquez | F12: PC-PROVINCIA2 | G12: I5-10400F | H12: 8GB 2600 MHZ DDR4 | I12: wvasquez | J12: 200
C13: 2 | D13: ACEPTABLE - CAMBIO | E13: Carlo Alva Gamarra | F13: PC-HORECA | G13: I5-6400 | H13: 8GB 2133 MHZ drr4 | I13: jroman | J13: 200
E14: Eduardo Rojas | F14: PC-CAMPO7 | G14: A12-9800E Radeon R7, 12 COMPUTE 4C+8G | H14: 8GB 1200MHZ drr3 | I14: jrios | J14: 200
E15: Jefferson Paz | F15: PC-ALMACEN1 | G15: I3-7100 | H15: 8GB 2400mhz DDR4 | I15: jpaz | J15: 200
E16: Jorge Rios | F16: LAP-VENTAS | G16: I5-8265U Intel | H16: 12GB 2400Mhz drr4 2 módulos 8 y 4 | I16: jrios | J16: 200
E17: Juditza Gonzales | F17: PC-MAYORISTA2 | G17: I3-7100U | H17: 8GB 2100MHZ DDR4 | I17: jgonzales | J17: 200
E18: Rosselyn Morante | F18: PC-VENTAS2 | G18: I5-6400 | H18: 8GB 2100MHZ DDR4 | I18: rmorante | J18: 200
E19: Virgilio gutierrez | F19: PC-PROVINCIAS | G19: I3-7100U | H19: 8GB 2133 MHZ drr4 | I19: vgutierrez | J19: 200
E20: Jhonny Davila | F20: PC-VENTAS4 | G20: I7-4790 | H20: 8GB 1600 MHZ DDR3 | I20: jbarboza | J20: 200
C21: 1 | D21: CAMBIO | E21: Jhon Rashta | F21: PC-DIGITACION2 | G21: I5-3330 intel | H21: 4GB drr3 1600mhz | I21: jrashta | J21: 200
E22: Nataly Cruz | F22: PC-TDA3 | G22: I3-7100 Intel | H22: 8GB 2400 MHZ DRR4 | I22: ncruz | J22: 200
E23: Ricardo Rojas | F23: PC-DIGITACION1 | G23: I5-3330 | H23: 4GB 1333 MHZ DRR3 | I23: rrojas | J23: 200
A24: CONTABILIDAD | B24: Contabilidad | C24: (en blanco) | D24: CAMBIO | E24: VELA CHUQUIPIO LIDIA MARITZA | F24: LAP-RRHH | G24: I5-7200 | H24: 16GB 3200MHZ DDR4 | I24: acontable | J24: 200
C25: #N/D | D25: (en blanco) | E25: I3 | F25: COMPUTADORA | G25: I7-1360P | H25: 16 GB drr4 3200MHZ | I25: FLORES RUBIN JACKELINE MERLY | J25: (en blanco)
C26: 3 | D26: OPTIMO - REPOTENCIAR | E26: Merly Flores | F26: PC-IMPORTACIONES2 | G26: I5-11400 | H26: 8GB 2666MHZ DDR4 | I26: acontable | J26: 200
C27: 1 | D27: CAMBIO | E27: FLORES RUBIN JACKELINE MERLY | F27: PC-CONTA2 | G27: I3-4160 | H27: 4GB 1600MHZ DDR3 | I27: acontable | J27: 200
B28: Facturacion | C28: 5 | D28: BUENA | E28: Frank Culqui Condor | F28: PC-DIGITACION3 | G28: I5-11400 | H28: 16GB 3200MHZ drr4 | I28: bcruz | J28: 177
C29: 2 | D29: ACEPTABLE - CAMBIO | E29: Rafael casaguaypa | F29: PC-IMPORTACIONES3 | G29: AMD A12 9800E RADEON R7 12 COMPUTER | H29: 8GB DDR3 1200MHZ | I29: bcruz | J29: 177
B30: Finanzas | C30: #N/D | D30: COMPRA | E30: (en blanco) | F30: (en blanco) | G30: I7-1360P | H30: 16GB 5200 MHZ DDR5 | I30: (en blanco) | J30: 200
A31: FINANZAS | B31: Cobranzas | C31: #N/D | D31: COMPRA | E31: LUISA LUYO | F31: LAP-GPCB003 | G31: RYZEN 7-7735HS | H31: 16GB 5200 MHZ DDR5 | I31: mluyo | J31: 200
D32: (en blanco) | E32: (en blanco) | F32: (en blanco) | G32: (en blanco) | H32: (en blanco) | I32: (en blanco) | J32: 200
E33: I3 | F33: COMPUTADORA | G33: I5-8265U | H33: 8GB DDR4 2400mhz | I33: Wilmer Amasifuen | J33: (en blanco)
C34: 3 | D34: OPTIMO - REPOTENCIAR | E34: Mirko Pari | F34: PC-COBRANZA4 | G34: I5-11400 2.6 GHZ | H34: 8GB 2600 MHZ drr4 | I34: mpari | J34: 200
C35: 2 | D35: ACEPTABLE - CAMBIO | E35: Kristell Quispe | F35: PC-CONTA3 | G35: I3-7100 Intel | H35: 8GB 3200MHZ DRR4 2 módulos de 4 | I35: kquispe | J35: 200
E36: Pedro Espejo | F36: PC-COBRANZA1 | G36: A12-9800E Radeon R7, 12 compute Cores 4C+8G | H36: 8GB 1200MHZ drr3 | I36: pespejo | J36: 200
C37: 1 | D37: CAMBIO | E37: Wilmer Amasifuen | F37: PC-COBRANZA2 | G37: I3-4170 intel | H37: 8GB 1600MHZ DRR3 | I37: wamasifuen | J37: 200
E38: HUANCA HUERTO, NICOLA REYMUNDO | F38: PC-COBRANZA3 | G38: I3-2120 intel | H38: 4GB 1333mhz drr3 | I38: nhuanca | J38: 200
B39: Contabilidad | C39: #N/D | D39: COMPRA | E39: Anthony Mendoza | F39: LAP-GPCB004 | G39: RYZEN 7-7735HS | H39: 16GB 5200 MHZ DDR5 | I39: amendoza | J39: 200
E40: Alfonso Pinedo | F40: (en blanco) | G40: I7-1360P | H40: 16GB 5200 MHZ DDR5 | I40: apinedo | J40: 177
C41: 3 | D41: OPTIMO - REPOTENCIAR | E41: Victor Ortiz | F41: PC-FINANZAS | G41: I5-9400F | H41: 8GB 2666MHZ DDR4 | I41: vortiz | J41: 200
C42: 1 | D42: CAMBIO | E42: SANCHEZ CAMINO MARIA VALERY | F42: PC-CONTA5 | G42: AMD A12 9800E-9800 | H42: 8GB 1200MHZ DDR3 | I42: msanchez | J42: 200
...

Sheet TD2
A3: Cont | I3: SEDE
A4: Estado2Valor | B4: Estado2 | C4: AREA | D4: SubArea | E4: TIPO | F4: PROCESADOR | G4: GENPROCESADOR | H4: RAM | I4: 177 | J4: 200 | K4: Nuevo local | L4: (en blanco) | M4: CAMBIO | N4: Total CAMBIO | O4: Total general
A5: (en blanco) | B5: CAMBIO | C5: CONTABILIDAD | D5: Contabilidad | E5: LAPTOP | F5: (en blanco) | G5: 7 | H5: 16GB | J5: 1 | O5: 1
B6: Total CAMBIO | J6: 1 | O6: 1
B7: (en blanco) | C7: (en blanco) | D7: (en blanco) | E7: (en blanco) | F7: (en blanco) | G7: (en blanco) | H7: (en blanco)
B8: Total (en blanco)
A9: #N/D | B9: COMPRA | C9: CONTABILIDAD | D9: Finanzas | E9: LAPTOP | F9: I7 | G9: 13 | H9: 16GB
C10: FINANZAS | D10: Cobranzas | E10: LAPTOP | F10: RYZEN 7 | G10: 7 | H10: 16GB | J10: 1 | O10: 1
D11: Contabilidad | E11: LAPTOP | F11: I7 | G11: 13 | H11: 16GB
F12: RYZEN 7 | G12: 7 | H12: 16GB | J12: 1 | O12: 1
C13: LOGISTICA | D13: Almacen | E13: LAPTOP | F13: RYZEN 7 | G13: 7 | H13: 16GB | J13: 1 | O13: 1
D14: Distribucion | E14: (en blanco) | F14: I7 | G14: (en blanco) | H14: (en blanco)
D15: Operaciones | E15: LAPTOP | F15: I7 | G15: 13 | H15: 16GB
C16: PRODUCCION | D16: Desarrollo | E16: (en blanco) | F16: I7 | G16: (en blanco) | H16: (en blanco)
C17: SISTEMAS | D17: Sistemas | E17: (en blanco) | F17: I7 | G17: (en blanco) | H17: (en blanco)
C18: (en blanco) | D18: (en blanco) | E18: (en blanco) | F18: I7 | G18: (en blanco) | H18: (en blanco)
B19: Total COMPRA | J19: 3 | O19: 3
B20: (en blanco) | C20: COMERCIAL | D20: Ventas | E20: LAPTOP | F20: RYZEN 7 | G20: 7 | H20: 16GB | M20: 1 | O20: 1
C21: CONTABILIDAD | D21: Contabilidad | E21: LAPTOP | F21: I7 | G21: 13 | H21: 16GB | L21: 1 | O21: 1
C22: FINANZAS | D22: Cobranzas | E22: LAPTOP | F22: I5 | G22: 8 | H22: 8GB | L22: 1 | O22: 1
E23: (en blanco) | F23: (en blanco) | G23: (en blanco) | H23: (en blanco)
C24: GGHH | D24: RRHH | E24: COMPUTADORA | F24: I3 | G24: 7 | H24: 8GB | L24: 1 | O24: 1
C25: (en blanco) | D25: Contabilidad | E25: COMPUTADORA | F25: I5 | G25: 11 | H25: 16GB | L25: 1 | O25: 1
D26: SSOMA | E26: COMPUTADORA | F26: I5 | G26: 3 | H26: 6GB | L26: 1 | O26: 1
D27: (en blanco) | E27: COMPUTADORA | F27: I5 | G27: 10 | H27: 8GB
G28: 11 | H28: 8GB
F29: I7 | G29: 11 | H29: 16GB
E30: LAPTOP | F30: I5 | G30: 12 | H30: 8GB
E31: (en blanco) | F31: (en blanco) | G31: (en blanco) | H31: (en blanco)
B32: Total (en blanco) | L32: 5 | M32: 1 | O32: 6
B33: 1 | C33: PRODUCCION | D33: Desarrollo | E33: COMPUTADORA | F33: I7 | G33: 4 | H33: 8GB | L33: 1 | O33: 1
C34: (en blanco) | D34: (en blanco) | E34: LAPTOP | F34: I7 | G34: 13 | H34: 16GB
B35: Total 1 | L35: 1 | O35: 1
A36: 5 | B36: BUENA | C36: CALIDAD | D36: Calidad | E36: COMPUTADORA | F36: I5 | G36: 11 | H36: 16GB | I36: 1 | O36: 1
E37: LAPTOP | F37: I7 | G37: 12 | H37: 16GB | I37: 1 | O37: 1
C38: COMERCIAL | D38: Ventas | E38: COMPUTADORA | F38: I7 | G38: 11 | H38: 16GB | J38: 2 | O38: 2
E39: LAPTOP | F39: I7 | G39: 12 | H39: 16GB | J39: 1 | O39: 1
C40: CONTABILIDAD | D40: Facturacion | E40: COMPUTADORA | F40: I5 | G40: 11 | H40: 16GB | I40: 1 | O40: 1
C41: LOGISTICA | D41: Almacen | E41: COMPUTADORA | F41: I5 | G41: 11 | H41: 16GB | I41: 2 | O41: 2
D42: Despacho | E42: LAPTOP | F42: I7 | G42: 7 | H42: 16GB | I42: 1 | O42: 1
...

Sheet TD2 (2)
A3: Cont | J3: SEDE
A4: Estado2Valor | B4: Estado2 | C4: AREA | D4: SubArea | E4: TIPO | F4: Responsable | G4: PROCESADOR | H4: GENPROCESADOR | I4: RAM | J4: 177 | K4: 200 | L4: Nuevo local | M4: (en blanco) | N4: CAMBIO | O4: Total CAMBIO | P4: Total general
A5: (en blanco) | B5: CAMBIO | C5: CONTABILIDAD | D5: Contabilidad | E5: LAPTOP | F5: VELA CHUQUIPIO LIDIA MARITZA | G5: (en blanco) | H5: 7 | I5: 16GB | K5: 1 | P5: 1
B6: (en blanco) | C6: (en blanco) | D6: (en blanco) | E6: (en blanco) | F6: (en blanco) | G6: (en blanco) | H6: (en blanco) | I6: (en blanco)
A7: #N/D | B7: 1 | C7: PRODUCCION | D7: Desarrollo | E7: COMPUTADORA | F7: PENTIUM | G7: I7 | H7: 4 | I7: 8GB | M7: 1 | P7: 1
C8: (en blanco) | D8: (en blanco) | E8: LAPTOP | F8: (en blanco) | G8: I7 | H8: 13 | I8: 16GB
B9: COMPRA | C9: CONTABILIDAD | D9: Finanzas | E9: LAPTOP | F9: (en blanco) | G9: I7 | H9: 13 | I9: 16GB
C10: FINANZAS | D10: Cobranzas | E10: LAPTOP | F10: LUISA LUYO | G10: RYZEN 7 | H10: 7 | I10: 16GB | K10: 1 | P10: 1
D11: Contabilidad | E11: LAPTOP | F11: Anthony Mendoza | G11: RYZEN 7 | H11: 7 | I11: 16GB | K11: 1 | P11: 1
F12: Alfonso Pinedo | G12: I7 | H12: 13 | I12: 16GB
C13: LOGISTICA | D13: Almacen | E13: LAPTOP | F13: VICTOR HUAMAN | G13: RYZEN 7 | H13: 7 | I13: 16GB | K13: 1 | P13: 1
D14: Distribucion | E14: (en blanco) | F14: (en blanco) | G14: I7 | H14: (en blanco) | I14: (en blanco)
D15: Operaciones | E15: LAPTOP | F15: (en blanco) | G15: I7 | H15: 13 | I15: 16GB
C16: PRODUCCION | D16: Desarrollo | E16: (en blanco) | F16: (en blanco) | G16: I7 | H16: (en blanco) | I16: (en blanco)
C17: SISTEMAS | D17: Sistemas | E17: (en blanco) | F17: (en blanco) | G17: I7 | H17: (en blanco) | I17: (en blanco)
C18: (en blanco) | D18: (en blanco) | E18: (en blanco) | F18: (en blanco) | G18: I7 | H18: (en blanco) | I18: (en blanco)
B19: (en blanco) | C19: COMERCIAL | D19: Ventas | E19: LAPTOP | F19: I5 | G19: RYZEN 7 | H19: 7 | I19: 16GB | N19: 1 | P19: 1
C20: CONTABILIDAD | D20: Contabilidad | E20: LAPTOP | F20: I3 | G20: I7 | H20: 13 | I20: 16GB | M20: 1 | P20: 1
C21: FINANZAS | D21: Cobranzas | E21: LAPTOP | F21: I3 | G21: I5 | H21: 8 | I21: 8GB | M21: 1 | P21: 1
E22: (en blanco) | F22: (en blanco) | G22: (en blanco) | H22: (en blanco) | I22: (en blanco)
C23: GGHH | D23: RRHH | E23: COMPUTADORA | F23: I5 | G23: I3 | H23: 7 | I23: 8GB | M23: 1 | P23: 1
C24: (en blanco) | D24: Contabilidad | E24: COMPUTADORA | F24: I7 AMD | G24: I5 | H24: 11 | I24: 16GB | M24: 1 | P24: 1
D25: SSOMA | E25: COMPUTADORA | F25: I3 | G25: I5 | H25: 3 | I25: 6GB | M25: 1 | P25: 1
D26: (en blanco) | E26: COMPUTADORA | F26: I5 | G26: I5 | H26: 10 | I26: 8GB
G27: I7 | H27: 11 | I27: 16GB
F28: I3 | G28: I5 | H28: 11 | I28: 8GB
G29: I7 | H29: 11 | I29: 16GB
F30: I7 | G30: I7 | H30: 11 | I30: 16GB
E31: LAPTOP | F31: I7 AMD | G31: I5 | H31: 12 | I31: 8GB
E32: (en blanco) | F32: (en blanco) | G32: (en blanco) | H32: (en blanco) | I32: (en blanco)
A33: 5 | B33: BUENA | C33: CALIDAD | D33: Calidad | E33: COMPUTADORA | F33: Maria Moran | G33: I5 | H33: 11 | I33: 16GB | J33: 1 | P33: 1
E34: LAPTOP | F34: Deysi Lopez | G34: I7 | H34: 12 | I34: 16GB | J34: 1 | P34: 1
C35: COMERCIAL | D35: Ventas | E35: COMPUTADORA | F35: Alexandra Roman | G35: I7 | H35: 11 | I35: 16GB | K35: 1 | P35: 1
F36: Lesly Quispe | G36: I7 | H36: 11 | I36: 16GB | K36: 1 | P36: 1
E37: LAPTOP | F37: Juan Pablo Quiroz Auqui | G37: I7 | H37: 12 | I37: 16GB | K37: 1 | P37: 1
C38: CONTABILIDAD | D38: Facturacion | E38: COMPUTADORA | F38: Frank Culqui Condor | G38: I5 | H38: 11 | I38: 16GB | J38: 1 | P38: 1
C39: LOGISTICA | D39: Almacen | E39: COMPUTADORA | F39: Joseph Rashta | G39: I5 | H39: 11 | I39: 16GB | J39: 1 | P39: 1
F40: Omar Cruz | G40: I5 | H40: 11 | I40: 16GB | J40: 1 | P40: 1
D41: Despacho | E41: LAPTOP | F41: Jeferson Amaro | G41: I7 | H41: 7 | I41: 16GB | J41: 1 | P41: 1
D42: Importaciones | E42: COMPUTADORA | F42: Luis Pare | G42: I5 | H42: 11 | I42: 16GB | K42: 1 | P42: 1
...

Sheet INV20260126
A1: SEDE | B1: AREA | C1: SubArea | D1: HOSTNAME | E1: usuario | F1: Responsable | G1: Cargo | H1: Estado1 | I1: Estado2 | J1: Estado4 | K1: TipoEQ | L1: TipoDES | M1: Estado2Valor | N1: Estado3 | O1: PROCESADOR | P1: GENPROCESADOR | Q1: DESCPROCESADOR | R1: TIPO | S1: MARCA | T1: DESCPLACAMADRE | U1: RAM | V1: DESCRAM | W1: DISCO | X1: DESCDISCO | Y1: Monitor | Z1: DESCMONITOR | AA1: PERIFERICOS | AB1: Estabilizador | AC1: Observaciones
A2: 200 | B2: LOGISTICA | C2: Importaciones | D2: LAP-DAMACENG | E2: emontoya | F2: Emily Montoya | G2: Responsable | H2: Activo | I2: BUENA | J2: Pendiente | K2: Laptop | L2: i7-135620h | 16GB DDR5| SSD 512GB| 15.6FHD | M2: =VLOOKUP(TabINV2026[[#This Row],[Estado2]],Tabla!$A$2:$B$6,2,FALSE) -> 5 | N2: BUENA | O2: I5 | P2: 10 | Q2: I5-10210U | R2: LAPTOP | S2: LENOVO | T2: Laptop L15 GEN 1 | U2: 16GB | V2: 16GB 3200MHZ drr4 | W2: SATA 240GB | X2: 240 GB SSD sata | Y2: 15.6 LENOVO | Z2: 15.6"" lenovo laptop | AA2: Cargador 65W CAN ICES-3(B) Teclado logitech membrana | AB2: Forza FVR 902 | AC2: Lentitud de red, temperatura caliente por horas de uso continuo.
A3: 200 | B3: LOGISTICA | C3: Importaciones | D3: LAP-PLANNER | E3: projas | F3: Paulo Rojas | G3: Lider | H3: Activo | I3: BUENA | J3: Pendiente | K3: Laptop | L3: i7-135620h | 16GB DDR5| SSD 512GB| 15.6FHD | M3: =VLOOKUP(TabINV2026[[#This Row],[Estado2]],Tabla!$A$2:$B$6,2,FALSE) -> 5 | N3: BUENA | O3: I7 | P3: 12 | Q3: I7-12700H | R3: LAPTOP | S3: ASUS | T3: Laptop Asus Vivobook | U3: 16GB | V3: 16GB 3200MHZ DRR4 | W3: M.2 512GB | X3: NVME M.2 MTFDKBK512QFM 512GB | Y3: 15.6 LENOVO | Z3: 15.6 LAPTOP | AA3: Mouse, mousepad, Cargador ASUS AD2087320 | AB3: Forza FVR-902 | AC3: Suciedad en la laptop futuro mantenimiento.
A4: 200 | B4: LOGISTICA | C4: Importaciones | D4: PC-FACTURACION4 | E4: Lpare | F4: Luis Pare | H4: Activo | I4: BUENA | J4: Pendiente | K4: Laptop | L4: i7-135620h | 16GB DDR5| SSD 512GB| 15.6FHD | M4: =VLOOKUP(TabINV2026[[#This Row],[Estado2]],Tabla!$A$2:$B$6,2,FALSE) -> 5 | N4: BUENA | O4: I5 | P4: 11 | Q4: I5-11400 Intel | R4: COMPUTADORA | S4: COMPATIBLE | T4: B560M gigabyte | U4: 16GB | V4: 16GB 3200mhz drr4 | W4: SATA 240GB | X4: WD 2.5 ssd sata 240GB | Y4: 24 SAMSUNG | Z4: Samsung S24R35AFHN 24" | AA4: Teclado genius, mouse logitech, estabilizador | AB4: forza fvr 902 | AC4: Teclado desgastado, mouse desgastado, pc mantenimiento suciedad en todo el case
A5: 200 | B5: FINANZAS | C5: Cobranzas | D5: PC-COBRANZA3 | E5: nhuanca | F5: HUANCA HUERTO, NICOLA REYMUNDO | G5: Responsable | H5: Activo | I5: CAMBIO | J5: Pendiente | K5: Laptop | L5: i7-135620h | 16GB DDR5| SSD 512GB| 15.6FHD | M5: =VLOOKUP(TabINV2026[[#This Row],[Estado2]],Tabla!$A$2:$B$6,2,FALSE) -> 1 | N5: CAMBIO Y VENTA | O5: I3 | P5: 2 | Q5: I3-2120 intel | R5: COMPUTADORA | S5: COMPATIBLE | T5: H61M-DS2 Gigabyte | U5: 4GB | V5: 4GB 1333mhz drr3 | W5: SATA 240GB | X5: WD 2.5 240GB | Y5: 22 SAMSUNG | Z5: Samsung S22F350FHL 22" | AA5: Teclado logitech, estabilizador | AB5: Estabilizador forza fvr 902 | AC5: Lentitud de pc por componentes antiguos cambio de pc, Teclado las teclas no se ven.
A6: 200 | B6: COMERCIAL | C6: Ventas | D6: PC-TDA3 | E6: ncruz | F6: Nataly Cruz | H6: Activo | I6: CAMBIO | J6: Pendiente | K6: Laptop | L6: i7-135620h | 16GB DDR5| SSD 512GB| 15.6FHD | M6: =VLOOKUP(TabINV2026[[#This Row],[Estado2]],Tabla!$A$2:$B$6,2,FALSE) -> 1 | N6: CAMBIO Y VENTA | O6: I3 | P6: 7 | Q6: I3-7100 Intel | R6: COMPUTADORA | S6: COMPATIBLE | T6: H110M-H Gigabyte | U6: 8GB | V6: 8GB 2400 MHZ DRR4 | W6: SATA 240GB | X6: WD 2.5 240GB | Y6: 22 SAMSUNG | Z6: Samsung S22FJ350FHL | AA6: Teclado logitech, mouse logitech | AB6: Estabilizador FVR 1202USB | AC6: PC con polvo futuro mantenimiento
A7: 200 | B7: FINANZAS | C7: Cobranzas | D7: PC-CONTA3 | E7: kquispe | F7: Kristell Quispe | G7: Responsable | H7: Activo | I7: ACEPTABLE - CAMBIO | J7: Pendiente | K7: Laptop | L7: i7-135620h | 16GB DDR5| SSD 512GB| 15.6FHD | M7: =VLOOKUP(TabINV2026[[#This Row],[Estado2]],Tabla!$A$2:$B$6,2,FALSE) -> 2 | N7: CAMBIO Y VENTA | O7: I3 | P7: 7 | Q7: I3-7100 Intel | R7: COMPUTADORA | S7: COMPATIBLE | T7: Asus prime H110M-P | U7: 8GB | V7: 8GB 3200MHZ DRR4 2 módulos de 4 | W7: SATA 240GB | X7: SSD Kingston SA400S37240G 240GB | Y7: 22 SAMSUNG | Z7: Samsung F22T350FHL | AA7: Estabilizador | AB7: TAIR PLI 1100USB | AC7: PC con polvo continuo en el case, futuro mantenimiento
A8: 200 | B8: FINANZAS | C8: Cobranzas | D8: PC-COBRANZA2 | E8: wamasifuen | F8: Wilmer Amasifuen | H8: Activo | I8: CAMBIO | J8: Pendiente | K8: PC | L8: I7 12700| PLACA ASUS H610| 16 GB DDR4 (2X8)| KINGSTON 500GB NV3 M.2| CASE HALIO + FUENTE DE PODER 500W| MONITOR SAMSUNG 27" IPS 1080P | M8: =VLOOKUP(TabINV2026[[#This Row],[Estado2]],Tabla!$A$2:$B$6,2,FALSE) -> 1 | N8: CAMBIO Y VENTA | O8: I3 | P8: 4 | Q8: I3-4170 intel | R8: COMPUTADORA | S8: COMPATIBLE | T8: H810M-H Gigabyte | U8: 8GB | V8: 8GB 1600MHZ DRR3 | W8: SATA 240GB | X8: Kingston SA400S37240G 240GB | Y8: 22 SAMSUNG | Z8: S22F35FHLXPE Samsung 22" | AA8: Teclad logitech, mouse genius | AB8: Gambyte | AC8: Mantenimiento pc sucia, componentes antiguos necesita actualización de equipo, lentitud de equipo
A9: 200 | B9: FINANZAS | C9: Cobranzas | D9: PC-COBRANZA4 | E9: mpari | F9: Mirko Pari | H9: Activo | I9: OPTIMO - REPOTENCIAR | J9: Pendiente | K9: PC | L9: I7 12700| PLACA ASUS H610| 16 GB DDR4 (2X8)| KINGSTON 500GB NV3 M.2| CASE HALIO + FUENTE DE PODER 500W| MONITOR SAMSUNG 27" IPS 1080P | M9: =VLOOKUP(TabINV2026[[#This Row],[Estado2]],Tabla!$A$2:$B$6,2,FALSE) -> 3 | N9: VENTA O REPOTENCIAR | O9: I5 | P9: 11 | Q9: I5-11400 2.6 GHZ | R9: COMPUTADORA | S9: COMPATIBLE | T9: Asus prime H510M-K R2.0 | U9: 8GB | V9: 8GB 2600 MHZ drr4 | W9: SATA 240GB | X9: MSI SPATIUM 240GB | Y9: 24 SAMSUNG | Z9: S24R35AFHN Samsung 24" | AA9: Teclado genios, mouse genius, estabilizador | AB9: No cuenta | AC9: Pc sucia mantenimiento futuro
A10: 200 | B10: FINANZAS | C10: Cobranzas | D10: PC-COBRANZA1 | E10: pespejo | F10: Pedro Espejo | H10: Activo | I10: ACEPTABLE - CAMBIO | J10: Pendiente | K10: PC | L10: I7 12700| PLACA ASUS H610| 16 GB DDR4 (2X8)| KINGSTON 500GB NV3 M.2| CASE HALIO + FUENTE DE PODER 500W| MONITOR SAMSUNG 27" IPS 1080P | M10: =VLOOKUP(TabINV2026[[#This Row],[Estado2]],Tabla!$A$2:$B$6,2,FALSE) -> 2 | N10: CAMBIO Y VENTA | O10: I7 AMD | P10: 5 | Q10: A12-9800E Radeon R7, 12 compute Cores 4C+8G | R10: COMPUTADORA | S10: COMPATIBLE | T10: Asustes PRIME A320M-K | U10: 8GB | V10: 8GB 1200MHZ drr3 | W10: SATA 240GB | X10: Kingston SA400S37240G 240GB | Y10: 24 SAMSUNG | Z10: S24R35AFHN Samsung 24" | AA10: Teclado Logitech, mouse logitech | AB10: Forza FVR 902 | AC10: Mantenimiento de pc suciedad en el case y componentes
A11: 200 | B11: COMERCIAL | C11: Ventas | D11: PC-CAMPO7 | E11: jrios | F11: Eduardo Rojas | H11: Activo | I11: ACEPTABLE - CAMBIO | J11: Pendiente | K11: Laptop | L11: i7-135620h | 16GB DDR5| SSD 512GB| 15.6FHD | M11: =VLOOKUP(TabINV2026[[#This Row],[Estado2]],Tabla!$A$2:$B$6,2,FALSE) -> 2 | N11: CAMBIO Y VENTA | O11: I7 AMD | P11: 5 | Q11: A12-9800E Radeon R7, 12 COMPUTE 4C+8G | R11: COMPUTADORA | S11: COMPATIBLE | T11: Asustek Prime A320MK | U11: 8GB | V11: 8GB 1200MHZ Drr3 | W11: SATA 240GB | X11: Kingston SA400S37240G 240GB | Y11: 19 LGI | Z11: 19M38A-B LG 19" | AA11: Teclado logitech, mouse logitech, mousepad | AB11: Forza-1002 | AC11: Problemas de energía, pc mantenimiento sucio case y componentes
A12: 200 | B12: COMERCIAL | C12: Ventas | D12: LAP-VENTAS | E12: jrios | F12: Jorge Rios | G12: Ventas | H12: Activo | I12: ACEPTABLE - CAMBIO | J12: Pendiente | K12: Laptop | L12: i7-135620h | 16GB DDR5| SSD 512GB| 15.6FHD | M12: =VLOOKUP(TabINV2026[[#This Row],[Estado2]],Tabla!$A$2:$B$6,2,FALSE) -> 2 | N12: CAMBIO Y VENTA | O12: I5 | P12: 8 | Q12: I5-8265U Intel | R12: LAPTOP | S12: LENOVO | T12: Laptop ipead s340-15iwl | U12: 12GB | V12: 12GB 2400Mhz drr4 2 módulos 8 y 4 | W12: SATA 240GB | X12: Kingston SA400S37240G 240GB | Y12: 15.6 LENOVO | Z12: 15.6 | AA12: Mouse y cargador laptop lenovo | AB12: PLI 1100 USB | AC12: Visagra rota, audio desperfecto, temperatura alta futuro mantenimiento
A13: 200 | B13: COMERCIAL | C13: Ventas | D13: PC-DIGITACION2 | E13: jrashta | F13: Jhon Rashta | G13: Ventas | H13: Activo | I13: CAMBIO | J13: Pendiente | K13: Laptop | L13: i7-135620h | 16GB DDR5| SSD 512GB| 15.6FHD | M13: =VLOOKUP(TabINV2026[[#This Row],[Estado2]],Tabla!$A$2:$B$6,2,FALSE) -> 1 | N13: CAMBIO Y VENTA | O13: I5 | P13: 3 | Q13: I5-3330 intel | R13: COMPUTADORA | S13: COMPATIBLE | T13: H61H2-MV ECS | U13: 4GB | V13: 4GB drr3 1600mhz | W13: SATA 240GB | X13: Kingston SA400S37240G 240GB | Y13: 24 LGI | Z13: 24mk430h-b LG 24" | AA13: Teclado logitech, mouse logitech | AB13: TAIR PLI 1100USB | AC13: Pc con lentitud, hardaware desactualizado, monitor con raya de Led desgaste.
A14: 200 | B14: COMERCIAL | C14: Ventas | D14: PC-HORECA | E14: jroman | F14: Carlo Alva Gamarra | G14: Ventas | H14: Activo | I14: ACEPTABLE - CAMBIO | J14: Pendiente | K14: Laptop | L14: i7-135620h | 16GB DDR5| SSD 512GB| 15.6FHD | M14: =VLOOKUP(TabINV2026[[#This Row],[Estado2]],Tabla!$A$2:$B$6,2,FALSE) -> 2 | N14: CAMBIO Y VENTA | O14: I5 | P14: 6 | Q14: I5-6400 | R14: COMPUTADORA | S14: COMPATIBLE | T14: Intel B250 | U14: 8GB | V14: 8GB 2133 MHZ drr4 | W14: SATA 240GB | X14: Gigabyte GP-GSTFS31240GNTD 240GB | Y14: 19 LGI | Z14: 19M38A-B LG 19" | AA14: Teclado logitech, mouse logitech | AB14: Forza FVR 902 | AC14: Mouse problemas, mantenimeinto de pc por temperatura
A15: 200 | B15: COMERCIAL | C15: Ventas | D15: PC-DIGITACION1 | E15: rrojas | F15: Ricardo Rojas | G15: Ventas | H15: Activo | I15: CAMBIO | J15: Pendiente | K15: Laptop | L15: i7-135620h | 16GB DDR5| SSD 512GB| 15.6FHD | M15: =VLOOKUP(TabINV2026[[#This Row],[Estado2]],Tabla!$A$2:$B$6,2,FALSE) -> 1 | N15: CAMBIO Y VENTA | O15: I5 | P15: 3 | Q15: I5-3330 | R15: COMPUTADORA | S15: COMPATIBLE | T15: H61M-DS2 3.0 | U15: 4GB | V15: 4GB 1333 MHZ DRR3 | W15: SATA 240GB | X15: Kingston SA400S37240G 240GB | Y15: 24 LGI | Z15: 24mk430h-b LG 24" | AA15: Teclado genius, mouse genius | AB15: Forza FVR 902 | AC15: Teclado desgastado, cable de video y puerto y mantenimeinto de pc por temperatura falta
A16: 200 | B16: COMERCIAL | C16: Ventas | D16: PC-PROVINCIAS | E16: vgutierrez | F16: Virgilio gutierrez | G16: Ventas | H16: Activo | I16: ACEPTABLE - CAMBIO | J16: Pendiente | K16: Laptop | L16: i7-135620h | 16GB DDR5| SSD 512GB| 15.6FHD | M16: =VLOOKUP(TabINV2026[[#This Row],[Estado2]],Tabla!$A$2:$B$6,2,FALSE) -> 2 | N16: CAMBIO Y VENTA | O16: I3 | P16: 7 | Q16: I3-7100U | R16: NUC | S16: INTEL | T16: NUC7i3BNB | U16: 8GB | V16: 8GB 2133 MHZ drr4 | W16: SATA 240GB | X16: Kingston SA400S37240G 240GB | Y16: 22 LGI | Z16: 22MK400H-B LG | AA16: Logitech teclado, genius mouse | AB16: CDP RU-AVR | AC16: Mantenimiento su mini PC
A17: 200 | B17: COMERCIAL | C17: Ventas | D17: PC-VENTAS4 | E17: jbarboza | F17: Jhonny Davila | H17: Activo | I17: ACEPTABLE - CAMBIO | J17: Pendiente | K17: Laptop | L17: i7-135620h | 16GB DDR5| SSD 512GB| 15.6FHD | M17: =VLOOKUP(TabINV2026[[#This Row],[Estado2]],Tabla!$A$2:$B$6,2,FALSE) -> 2 | N17: CAMBIO Y VENTA | O17: I7 | P17: 4 | Q17: I7-4790 | R17: COMPUTADORA | S17: COMPATIBLE | T17: H810M-H Gigabyte | U17: 8GB | V17: 8GB 1600 MHZ DDR3 | W17: SATA 240GB | X17: Gigabyte GP-GSTF31240GNTD | Y17: 19 LGI | Z17: 19M37A-B LG | AA17: Teclado genius, mouse Genius | AB17: Corriente directa | AC17: Mantenimeinto de pc, cambio de teclado y mouse desgaste
A18: 200 | B18: COMERCIAL | C18: Ventas | D18: PC-ALMACEN1 | E18: jpaz | F18: Jefferson Paz | G18: Ventas | H18: Activo | I18: ACEPTABLE - CAMBIO | J18: Pendiente | K18: Laptop | L18: i7-135620h | 16GB DDR5| SSD 512GB| 15.6FHD | M18: =VLOOKUP(TabINV2026[[#This Row],[Estado2]],Tabla!$A$2:$B$6,2,FALSE) -> 2 | N18: CAMBIO Y VENTA | O18: I3 | P18: 7 | Q18: I3-7100 | R18: COMPUTADORA | S18: COMPATIBLE | T18: Asustek Prime H110M-P | U18: 8GB | V18: 8GB 2400mhz DDR4 | W18: SATA 240GB | X18: WD 2.5 240GB | Y18: 24 LGI | Z18: 24mk430h-b LG 24" | AA18: Teclado logitech, mouse genius | AB18: UPS BX800L-MS | AC18: Congelamiento con pc, mantenimiento pc, Teclado esta mal.
A19: 200 | B19: COMERCIAL | C19: Ventas | D19: PC-MAYORISTA2 | E19: jgonzales | F19: Juditza Gonzales | H19: Activo | I19: ACEPTABLE - CAMBIO | J19: Pendiente | K19: PC | L19: I7 12700| PLACA ASUS H610| 16 GB DDR4 (2X8)| KINGSTON 500GB NV3 M.2| CASE HALIO + FUENTE DE PODER 500W| MONITOR SAMSUNG 27" IPS 1080P | M19: =VLOOKUP(TabINV2026[[#This Row],[Estado2]],Tabla!$A$2:$B$6,2,FALSE) -> 2 | N19: CAMBIO Y VENTA | O19: I3 | P19: 7 | Q19: I3-7100U | R19: NUC | S19: INTEL | T19: NUC7I3BNB intel | U19: 8GB | V19: 8GB 2100MHZ DDR4 | W19: SATA 240GB | X19: Kingston SA400S37240G 240GB | Y19: 24 SAMSUNG | Z19: S24R35AFHN Samsung 24" | AA19: Teclado logitech, Mouse logitech | AB19: UPS SPS ONE SALICRU, | AC19: Mantenimeinto pc físico y digital
A20: 200 | B20: COMERCIAL | C20: Ventas | D20: PC-VENTAS2 | E20: rmorante | F20: Rosselyn Morante | H20: Activo | I20: ACEPTABLE - CAMBIO | J20: Pendiente | K20: PC | L20: I7 12700| PLACA ASUS H610| 16 GB DDR4 (2X8)| KINGSTON 500GB NV3 M.2| CASE HALIO + FUENTE DE PODER 500W| MONITOR SAMSUNG 27" IPS 1080P | M20: =VLOOKUP(TabINV2026[[#This Row],[Estado2]],Tabla!$A$2:$B$6,2,FALSE) -> 2 | N20: CAMBIO Y VENTA | O20: I5 | P20: 6 | Q20: I5-6400 | R20: COMPUTADORA | S20: COMPATIBLE | T20: H110M-H-CF | U20: 8GB | V20: 8GB 2100MHZ DDR4 | W20: SATA 240GB | X20: WD 2.5 240GB | Y20: 22 LGI | Z20: 22M38H-B LG | AA20: Teclado genius, mouse genius | AB20: UPS SALICRU SPS ONE, forza fvr 1110 | AC20: Fuente de poder ventilador no funciona, mantenimiento a pc general
A21: 200 | B21: COMERCIAL | C21: Ventas | D21: PC-SISTEMAS2 | E21: jbarboza | F21: Alexandra Roman | G21: Ventas | H21: Activo | I21: BUENA | J21: Pendiente | K21: Laptop | L21: i7-135620h | 16GB DDR5| SSD 512GB| 15.6FHD | M21: =VLOOKUP(TabINV2026[[#This Row],[Estado2]],Tabla!$A$2:$B$6,2,FALSE) -> 5 | N21: BUENA | O21: I7 | P21: 11 | Q21: I7-11700 | R21: COMPUTADORA | S21: COMPATIBLE | T21: B560M D3SH | U21: 16GB | V21: 16GB 2666MHZ DDR4 | W21: SATA 500GB | X21: CT500P2SSD8 500GB | Y21: 24 SAMSUNG | Z21: S24R35AFHN Samsung 24" | AA21: Logitech Teclado, Mouse genius | AB21: UPS SALICRU SPS ONE | AC21: Mantenimiento PC temperatura alta
A22: 200 | B22: COMERCIAL | C22: Ventas | D22: PC-VENTAS3 | E22: lquispe | F22: Lesly Quispe | G22: Ventas | H22: Activo | I22: BUENA | J22: Pendiente | K22: Laptop | L22: i7-135620h | 16GB DDR5| SSD 512GB| 15.6FHD | M22: =VLOOKUP(TabINV2026[[#This Row],[Estado2]],Tabla!$A$2:$B$6,2,FALSE) -> 5 | N22: BUENA | O22: I7 | P22: 11 | Q22: I7-11700 | R22: COMPUTADORA | S22: COMPATIBLE | T22: B560M Gaming HD Gigabyte | U22: 16GB | V22: 16GB 2666MHZ DDR4 | W22: M.2 512GB | X22: DAHUA C900 2280 NVME 512GB M.2 | Y22: 24 LGI | Z22: 24MK430H-B LG 24" | AA22: Teclado logitech, mouse Logitech | AB22: UPS SALICRU SPS ONE | AC22: Mantenimiento PC temperatura alta
A23: 200 | B23: COMERCIAL | C23: Ventas | D23: PC-PROVINCIA2 | E23: wvasquez | F23: Walter Vasquez | G23: Ventas | H23: Activo | I23: OPTIMO - REPOTENCIAR | J23: Pendiente | K23: Laptop | L23: i7-135620h | 16GB DDR5| SSD 512GB| 15.6FHD | M23: =VLOOKUP(TabINV2026[[#This Row],[Estado2]],Tabla!$A$2:$B$6,2,FALSE) -> 3 | N23: VENTA O REPOTENCIAR | O23: I5 | P23: 10 | Q23: I5-10400F | R23: COMPUTADORA | S23: COMPATIBLE | T23: H410M S2H V2 | U23: 8GB | V23: 8GB 2600 MHZ DDR4 | W23: SATA 480GB | X23: CT480BX500SSD1 480 SSD | Y23: 24 SAMSUNG | Z23: F24T350FHL Samsung 24" | AA23: Teclado logitech, Mouse logitech | AB23: Forza FVR 902 | AC23: Insuficiente memoria ram, se apaga solo, mantenimiento pc por temperatura.
A24: 200 | B24: CONTABILIDAD | C24: Contabilidad | D24: PC-IMPORTACIONES2 | E24: acontable | F24: Merly Flores | H24: Activo | I24: OPTIMO - REPOTENCIAR | J24: Pendiente | K24: PC | L24: I7 12700| PLACA ASUS H610| 16 GB DDR4 (2X8)| KINGSTON 500GB NV3 M.2| CASE HALIO + FUENTE DE PODER 500W| MONITOR SAMSUNG 27" IPS 1080P | M24: =VLOOKUP(TabINV2026[[#This Row],[Estado2]],Tabla!$A$2:$B$6,2,FALSE) -> 3 | N24: VENTA O REPOTENCIAR | O24: I5 | P24: 11 | Q24: I5-11400 | R24: COMPUTADORA | S24: COMPATIBLE | T24: PRIME H510M-K R2.0 | U24: 8GB | V24: 8GB 2666MHZ DDR4 | W24: SATA 240GB | X24: Kingston SA400S37240G 240GB | Y24: 20 LGI | Z24: 20M47A-B LG | AA24: Teclado genius, mouse logitech | AB24: Gambyte | AC24: Insuficiente memoria ram, mantenimiento por temperatura alta
A25: 200 | B25: FINANZAS | C25: Contabilidad | D25: PC-CONTA5 | E25: msanchez | F25: SANCHEZ CAMINO MARIA VALERY | G25: asistente de contabilidad | H25: Activo | I25: CAMBIO | J25: Pendiente | K25: PC | L25: I7 12700| PLACA ASUS H610| 16 GB DDR4 (2X8)| KINGSTON 500GB NV3 M.2| CASE HALIO + FUENTE DE PODER 500W| MONITOR SAMSUNG 27" IPS 1080P | M25: =VLOOKUP(TabINV2026[[#This Row],[Estado2]],Tabla!$A$2:$B$6,2,FALSE) -> 1 | N25: CAMBIO Y VENTA | O25: I7 AMD | P25: 5 | Q25: AMD A12 9800E-9800 | R25: COMPUTADORA | S25: COMPATIBLE | T25: Prime A320M-K | U25: 8GB | V25: 8GB 1200MHZ DDR3 | W25: SATA 240GB | X25: WD 2.5 GREEN 240GB | Y25: 24 SAMSUNG | Z25: S24R35AFHN Samsung 24" | AA25: Teclado genius, mouse genius | AB25: Quedar modelo | AC25: Mantenimeinto pc, componentes obsoletos
A26: 200 | B26: CONTABILIDAD | C26: Contabilidad | D26: PC-CONTA2 | E26: acontable | F26: FLORES RUBIN JACKELINE MERLY | G26: Asistente contable | H26: Activo | I26: CAMBIO | J26: Pendiente | K26: PC | L26: I7 12700| PLACA ASUS H610| 16 GB DDR4 (2X8)| KINGSTON 500GB NV3 M.2| CASE HALIO + FUENTE DE PODER 500W| MONITOR SAMSUNG 27" IPS 1080P | M26: =VLOOKUP(TabINV2026[[#This Row],[Estado2]],Tabla!$A$2:$B$6,2,FALSE) -> 1 | N26: CAMBIO Y VENTA | O26: I3 | P26: 4 | Q26: I3-4160 | R26: COMPUTADORA | S26: COMPATIBLE | T26: H810M-H Gigabyte | U26: 4GB | V26: 4GB 1600MHZ DDR3 | W26: SATA 240GB | X26: WD 2.5 Green 240GB | Y26: 22 LGI | Z26: 22MK400H-B LG 22"" | AA26: Teclado logitech, mouse genius | AB26: Forza FVR 902 | AC26: Mantenimiento pc, ampliación de memoria ram insuficiente
A27: 200 | B27: FINANZAS | C27: Contabilidad | D27: PC-CONTA6 | E27: acostos | F27: Beatriz | H27: Activo | I27: CAMBIO | J27: Pendiente | K27: PC | L27: I7 12700| PLACA ASUS H610| 16 GB DDR4 (2X8)| KINGSTON 500GB NV3 M.2| CASE HALIO + FUENTE DE PODER 500W| MONITOR SAMSUNG 27" IPS 1080P | M27: =VLOOKUP(TabINV2026[[#This Row],[Estado2]],Tabla!$A$2:$B$6,2,FALSE) -> 1 | N27: CAMBIO Y VENTA | O27: I7 AMD | P27: 5 | Q27: AMD A12-9800E Radeon R7 12 Compute cores 4c+8G | R27: COMPUTADORA | S27: COMPATIBLE | T27: Prime A320M-K | U27: 8GB | V27: 8GB 1200MHZ DDR3 | W27: SATA 240GB | X27: Kingston SA400S37240G 240GB | Y27: 22 LGI | Z27: 22M38H-B LG 22" | AA27: Teclado genius, mouse logitech | AB27: Forza FVR 902 | AC27: Lentitud ordenador urgente, cuelgue de la maquina constante, mantenimiento ordenador.
A28: 200 | B28: FINANZAS | C28: Contabilidad | D28: PC-FINANZAS | E28: vortiz | F28: Victor Ortiz | G28: Lider | H28: Activo | I28: OPTIMO - REPOTENCIAR | J28: Pendiente | K28: PC | L28: I7 12700| PLACA ASUS H610| 16 GB DDR4 (2X8)| KINGSTON 500GB NV3 M.2| CASE HALIO + FUENTE DE PODER 500W| MONITOR SAMSUNG 27" IPS 1080P | M28: =VLOOKUP(TabINV2026[[#This Row],[Estado2]],Tabla!$A$2:$B$6,2,FALSE) -> 3 | N28: VENTA O REPOTENCIAR | O28: I5 | P28: 9 | Q28: I5-9400F | R28: COMPUTADORA | S28: COMPATIBLE | T28: H310M H 2m0 | U28: 8GB | V28: 8GB 2666MHZ DDR4 | W28: SATA 480GB | X28: WDC WDS480G2G0A-00JH30 480GB | Y28: 22 SAMSUNG | Z28: S22F35FHLXPE Samsung 22" | AA28: Teclado genius, mouse logitech | AB28: Estabilizador | AC28: Lentitud ordenador, mantenimiento y upgrade memoria ram
A29: 200 | B29: COMERCIAL | C29: Marketing | D29: PC-MARKETING | E29: fleon | F29: Alexander Flores | G29: Responsable | H29: Activo | I29: BUENA - REPOTENCIAR | J29: Pendiente | K29: Laptop | L29: i7-135620h | 16GB DDR5| SSD 512GB| 15.6FHD | M29: =VLOOKUP(TabINV2026[[#This Row],[Estado2]],Tabla!$A$2:$B$6,2,FALSE) -> 4 | N29: BUENA | O29: I7 | P29: 11 | Q29: I7-11700 | R29: COMPUTADORA | S29: COMPATIBLE | T29: B560M Gigabyte | U29: 16GB | V29: 16GB | W29: SATA 500GB | X29: SSD 500 CT480BX500SSD1 | Y29: 24 SAMSUNG | Z29: FN24T350FHL, SAMSUNG, 24" | AA29: Mouse genius y teclado genius | AB29: FORZA FVR 902 | AC29: Pantallazo Azul, tiene freeze el ordenador, memoria ram un modulo defectuosa, ya que es una compatible y no original
A30: 200 | B30: COMERCIAL | C30: Ventas | D30: LAP-FINANZAS | E30: jquiroz | F30: Juan Pablo Quiroz Auqui | G30: Lider | H30: Activo | I30: BUENA | J30: Pendiente | K30: Laptop | L30: i7-135620h | 16GB DDR5| SSD 512GB| 15.6FHD | M30: =VLOOKUP(TabINV2026[[#This Row],[Estado2]],Tabla!$A$2:$B$6,2,FALSE) -> 5 | N30: BUENA | O30: I7 | P30: 12 | Q30: I7-1255U | R30: LAPTOP | S30: DELL | T30: LAPTOP DELL INSPIRION15 3520 | U30: 16GB | V30: 16GB | W30: M.2 1024GB | X30: NVME BG6 KIOXIA 1024GB | Y30: 15.6" DELL | Z30: 15.6" | AA30: CARGADOR DELL (19.5V - 3.34A – 65.0W) | AB30: no | AC30: Visagra reparada, se requiere tener cuidado y hacerle mantenimiento con observaciones constantes
A31: 200 | B31: GGHH | C31: SSOMA | D31: PC-SSOMA | E31: agonzales | F31: Adrian Gonzales | G31: Responsable | H31: Activo | I31: CAMBIO | J31: Pendiente | K31: PC | L31: I7 12700| PLACA ASUS H610| 16 GB DDR4 (2X8)| KINGSTON 500GB NV3 M.2| CASE HALIO + FUENTE DE PODER 500W| MONITOR SAMSUNG 27" IPS 1080P | M31: =VLOOKUP(TabINV2026[[#This Row],[Estado2]],Tabla!$A$2:$B$6,2,FALSE) -> 1 | N31: CAMBIO Y VENTA | O31: I3 | P31: 4 | Q31: I3-4170 | R31: COMPUTADORA | S31: COMPATIBLE | T31: H810M-H | U31: 8GB | V31: 8GB 1600MHZ DDR3 | W31: SATA 240GB | X31: Kingston SA400S37240G 240GB | Y31: 19 LGI | Z31: 19M38A-B LG 19" | AA31: Teclado y mouse | AB31: Forza FVR 902 | AC31: Pc lenta, memoria ram insuficiente
